<mujoco model="2DofArm">
    <default>
        <geom type="mesh" xyaxes="1 0 0 0 1 0"/>
    </default>
    <asset>
        <mesh name="Arm" file="Arm.stl" scale="0.001 0.001 0.001"/>
        <mesh name="ArmMotor" file="ArmMotor.stl" scale="0.001 0.001 0.001"/>
        <mesh name="BaseMotor" file="BaseMotor.stl" scale="0.001 0.001 0.001"/>
        <mesh name="MujocoBase" file="MujocoBase.stl" scale="0.001 0.001 0.001"/>
    </asset>
    <worldbody>
        <body name="MujocoBase">
            <geom mesh="MujocoBase"/>
            <body name="BaseMotor">
                <geom mesh="BaseMotor"/>
                <body name="Arm">
                    <joint name="joint_1" pos="0 0 0" axis="1 0 0" limited="false"/>
                    <geom mesh="Arm"/>
                    <body name="ArmMotor">
                        <geom mesh="ArmMotor"/>
                    </body>
                </body>
            </body>
        </body>
    </worldbody>
    <actuator>
        <position name="joint_1" joint="joint_1" ctrllimited="true" ctrlrange="-3.14 3.14" kp="1" kv="0.4"/>
    </actuator>
</mujoco>